<?xml version="1.0" ?>
<!-- =================================================================================== -->
<!-- |    This document was autogenerated by xacro from ./hopejr_hand.xacro            | -->
<!-- |    EDITING THIS FILE BY HAND IS NOT RECOMMENDED                                 | -->
<!-- =================================================================================== -->
<robot name="hopejr_hand">
  <link name="base_footprint"/>
  <link name="base_link">
    <visual>
      <origin rpy="0.0 0 0" xyz="0 0 0"/>
      <geometry>
        <mesh filename="package://hopejr_hand_description/meshes/visual/base_link.dae" scale="0.1 0.1 0.1"/>
      </geometry>
    </visual>
    <collision>
      <origin rpy="0 0 0" xyz="0 0 0"/>
      <geometry>
        <mesh filename="package://hopejr_hand_description/meshes/collision/base_link.stl" scale="0.1 0.1 0.1"/>
      </geometry>
    </collision>
    <inertial>
      <origin rpy="0 0 0" xyz="-0.02 0 0.028"/>
      <mass value="0.03323"/>
      <inertia ixx="0.000018824494" ixy="-0.000000571474" ixz="-0.000000041098" iyy="0.00001505929" iyz="0.000000023636" izz="0.000013661405"/>
    </inertial>
  </link>
  <link name="hand">
    <visual>
      <origin rpy="0 0 0" xyz="0 0 0"/>
      <geometry>
        <mesh filename="package://hopejr_hand_description/meshes/visual/hand.dae" scale="0.1 0.1 0.1"/>
      </geometry>
    </visual>
    <collision>
      <origin rpy="0 0 0" xyz="0 0 0"/>
      <geometry>
        <mesh filename="package://hopejr_hand_description/meshes/collision/hand.stl" scale="0.1 0.1 0.1"/>
      </geometry>
    </collision>
    <inertial>
      <origin rpy="0 0 0" xyz="0 0 0"/>
      <mass value="0.252893"/>
      <inertia ixx="0.0002839" ixy="0.000003336317" ixz="0.000004077546" iyy="0.0001891" iyz="0.000000331897" izz="0.0001469"/>
    </inertial>
  </link>
  <joint name="wrist_pitch" type="revolute">
    <parent link="base_link"/>
    <child link="hand"/>
    <origin rpy="0 1.5707963267948966 0" xyz="0.029887000000000004 0.007923 0"/>
    <axis xyz="0 1 0"/>
    <limit effort="10" lower="-1.3089969389957472" upper="1.3962634015954636" velocity="1.0"/>
  </joint>
  <link name="thumb_mcp_2">
    <visual>
      <origin rpy="0 0 0" xyz="0 0 0"/>
      <geometry>
        <mesh filename="package://hopejr_hand_description/meshes/visual/thumb_mcp_2.dae" scale="0.1 0.1 0.1"/>
      </geometry>
    </visual>
    <collision>
      <origin rpy="0 0 0" xyz="0 0 0"/>
      <geometry>
        <mesh filename="package://hopejr_hand_description/meshes/collision/thumb_mcp_2.stl" scale="0.1 0.1 0.1"/>
      </geometry>
    </collision>
    <inertial>
      <origin rpy="0 0 0" xyz="0 0 0"/>
      <mass value="0.008776"/>
      <inertia ixx="0.000000783215" ixy="0.000000007992" ixz="0.000000266897" iyy="0.000000932685" iyz="-0.000000055174" izz="0.000000534905"/>
    </inertial>
  </link>
  <joint name="thumb_mcp_2" type="revolute">
    <parent link="hand"/>
    <child link="thumb_mcp_2"/>
    <origin rpy="2.722713633111154 0.19198621771937624 -1.1693705988362009" xyz="0.019772 0.028618 0.0058046"/>
    <axis xyz="0 0 1"/>
    <limit effort="10" lower="-3" upper="-0.043" velocity="1.0"/>
  </joint>
  <link name="thumb_pip_1_support">
    <inertial>
      <origin rpy="0 0 0" xyz="0 0 0"/>
      <mass value="0.0000000000001"/>
      <inertia ixx="0.00000000000001" ixy="0" ixz="0" iyy="0.00000000000001" iyz="0" izz="0.00000000000001"/>
    </inertial>
  </link>
  <joint name="thumb_pip_1_support" type="revolute">
    <parent link="thumb_mcp_2"/>
    <child link="thumb_pip_1_support"/>
    <origin rpy="-2.748893571891069 1.1192796493039634 -0.36257469880930204" xyz="0.01180315 -0.0012147500000000001 -0.0229186"/>
    <axis xyz="0 -1 0"/>
    <limit effort="10" lower="0" upper="1.1780972450961724" velocity="1.0"/>
    <mimic joint="thumb_pip_1"/>
  </joint>
  <link name="thumb_pip_1">
    <visual>
      <origin rpy="0 0 0" xyz="0 0 0"/>
      <geometry>
        <mesh filename="package://hopejr_hand_description/meshes/visual/thumb_pip_1.dae" scale="0.1 0.1 0.1"/>
      </geometry>
    </visual>
    <collision>
      <origin rpy="0 0 0" xyz="0 0 0"/>
      <geometry>
        <mesh filename="package://hopejr_hand_description/meshes/collision/thumb_pip_1.stl" scale="0.1 0.1 0.1"/>
      </geometry>
    </collision>
    <inertial>
      <origin rpy="0 0 0" xyz="0 0 0"/>
      <mass value="0.007142"/>
      <inertia ixx="0.000000233324" ixy="-0.000000000007" ixz="0.00000000023" iyy="0.000000597862" iyz="0.000000000054" izz="0.000000638412"/>
    </inertial>
  </link>
  <joint name="thumb_pip_1" type="revolute">
    <parent link="thumb_pip_1_support"/>
    <child link="thumb_pip_1"/>
    <origin rpy="0 0 0" xyz="0.0152 0 0"/>
    <axis xyz="0 -1 0"/>
    <limit effort="10" lower="0" upper="1.1780972450961724" velocity="1.0"/>
  </joint>
  <link name="thumb_pip_2_support">
    <inertial>
      <origin rpy="0 0 0" xyz="0 0 0"/>
      <mass value="0.0000000000001"/>
      <inertia ixx="0.00000000000001" ixy="0" ixz="0" iyy="0.00000000000001" iyz="0" izz="0.00000000000001"/>
    </inertial>
  </link>
  <joint name="thumb_pip_2_support" type="revolute">
    <parent link="thumb_pip_1"/>
    <child link="thumb_pip_2_support"/>
    <origin rpy="0 0 0" xyz="0.016800000000000002 0 0"/>
    <axis xyz="0 -1 0"/>
    <limit effort="10" lower="0" upper="1.1780972450961724" velocity="1.0"/>
    <mimic joint="thumb_pip_2"/>
  </joint>
  <link name="thumb_pip_2">
    <visual>
      <origin rpy="0 0 0" xyz="0 0 0"/>
      <geometry>
        <mesh filename="package://hopejr_hand_description/meshes/visual/thumb_pip_2.dae" scale="0.1 0.1 0.1"/>
      </geometry>
    </visual>
    <collision>
      <origin rpy="0 0 0" xyz="0 0 0"/>
      <geometry>
        <mesh filename="package://hopejr_hand_description/meshes/collision/thumb_pip_2.stl" scale="0.1 0.1 0.1"/>
      </geometry>
    </collision>
    <inertial>
      <origin rpy="0 0 0" xyz="0 0 0"/>
      <mass value="0.006089"/>
      <inertia ixx="0.000000197597" ixy="-0.000000000005" ixz="0.00000000043" iyy="0.000000404632" iyz="0.000000000054" izz="0.000000440963"/>
    </inertial>
  </link>
  <joint name="thumb_pip_2" type="revolute">
    <parent link="thumb_pip_2_support"/>
    <child link="thumb_pip_2"/>
    <origin rpy="0 0 0" xyz="0.0152 0 0"/>
    <axis xyz="0 -1 0"/>
    <limit effort="10" lower="0" upper="1.1780972450961724" velocity="1.0"/>
  </joint>
  <link name="thumb_dip_support">
    <inertial>
      <origin rpy="0 0 0" xyz="0 0 0"/>
      <mass value="0.0000000000001"/>
      <inertia ixx="0.00000000000001" ixy="0" ixz="0" iyy="0.00000000000001" iyz="0" izz="0.00000000000001"/>
    </inertial>
  </link>
  <joint name="thumb_dip_support" type="revolute">
    <parent link="thumb_pip_2"/>
    <child link="thumb_dip_support"/>
    <origin rpy="0 0 0" xyz="0.0128 0 0"/>
    <axis xyz="0 -1 0"/>
    <limit effort="10" lower="0" upper="1.1780972450961724" velocity="1.0"/>
    <mimic joint="thumb_dip"/>
  </joint>
  <link name="thumb_dip">
    <visual>
      <origin rpy="0 0 0" xyz="0 0 0"/>
      <geometry>
        <mesh filename="package://hopejr_hand_description/meshes/visual/thumb_dip.dae" scale="0.1 0.1 0.1"/>
      </geometry>
    </visual>
    <collision>
      <origin rpy="0 0 0" xyz="0 0 0"/>
      <geometry>
        <mesh filename="package://hopejr_hand_description/meshes/collision/thumb_dip.stl" scale="0.1 0.1 0.1"/>
      </geometry>
    </collision>
    <inertial>
      <origin rpy="0 0 0" xyz="0 0 0"/>
      <mass value="0.005429"/>
      <inertia ixx="0.000000155671" ixy="0.000000000024" ixz="0.000000002166" iyy="0.00000033961" iyz="0.000000000002" izz="0.000000357923"/>
    </inertial>
  </link>
  <joint name="thumb_dip" type="revolute">
    <parent link="thumb_dip_support"/>
    <child link="thumb_dip"/>
    <origin rpy="0 0 0" xyz="0.0152 0 0"/>
    <axis xyz="0 -1 0"/>
    <limit effort="10" lower="0" upper="1.1780972450961724" velocity="1.0"/>
  </joint>
  <link name="index_mcp_1">
    <visual>
      <origin rpy="0 0 0" xyz="0 0 0"/>
      <geometry>
        <mesh filename="package://hopejr_hand_description/meshes/visual/mcp_1.dae" scale="0.1 0.1 0.1"/>
      </geometry>
    </visual>
    <collision>
      <origin rpy="0 0 0" xyz="0 0 0"/>
      <geometry>
        <mesh filename="package://hopejr_hand_description/meshes/collision/mcp_1.stl" scale="0.1 0.1 0.1"/>
      </geometry>
    </collision>
    <inertial>
      <origin rpy="0 0 0" xyz="0 0 0"/>
      <mass value="0.004836"/>
      <inertia ixx="0.000000235908" ixy="-0.000000006556" ixz="0.000000001806" iyy="0.000000740439" iyz="0.000000000035" izz="0.000000830731"/>
    </inertial>
  </link>
  <joint name="index_mcp_1" type="fixed">
    <parent link="hand"/>
    <child link="index_mcp_1"/>
    <origin rpy="-1.5494858566280458 -1.4832331582223413 1.5600625518951317" xyz="0.0071613 0.025677000000000002 0.085375"/>
    <axis xyz="0 1 0"/>
  </joint>
  <link name="index_mcp_2_support">
    <inertial>
      <origin rpy="0 0 0" xyz="0 0 0"/>
      <mass value="0.0000000000001"/>
      <inertia ixx="0.00000000000001" ixy="0" ixz="0" iyy="0.00000000000001" iyz="0" izz="0.00000000000001"/>
    </inertial>
  </link>
  <joint name="index_mcp_2_support" type="revolute">
    <parent link="index_mcp_1"/>
    <child link="index_mcp_2_support"/>
    <origin rpy="0 0 0" xyz="0 0 0"/>
    <axis xyz="0 1 0"/>
    <limit effort="10" lower="0" upper="1.1780972450961724" velocity="1.0"/>
    <mimic joint="index_mcp_2"/>
  </joint>
  <link name="index_mcp_2">
    <visual>
      <origin rpy="0 0 0" xyz="0 0 0"/>
      <geometry>
        <mesh filename="package://hopejr_hand_description/meshes/visual/mcp_2.dae" scale="0.1 0.1 0.1"/>
      </geometry>
    </visual>
    <collision>
      <origin rpy="0 0 0" xyz="0 0 0"/>
      <geometry>
        <mesh filename="package://hopejr_hand_description/meshes/collision/mcp_2.stl" scale="0.1 0.1 0.1"/>
      </geometry>
    </collision>
    <inertial>
      <origin rpy="0 0 0" xyz="0 0 0"/>
      <mass value="0.001654"/>
      <inertia ixx="0.000000049479" ixy="0.000000000263" ixz="0.000000000299" iyy="0.000000032432" iyz="0.000000000057" izz="0.000000038462"/>
    </inertial>
  </link>
  <joint name="index_mcp_2" type="revolute">
    <parent link="index_mcp_2_support"/>
    <child link="index_mcp_2"/>
    <origin rpy="0 0 0" xyz="0.0152 0 0"/>
    <axis xyz="0 1 0"/>
    <limit effort="10" lower="0" upper="1.1780972450961724" velocity="1.0"/>
  </joint>
  <link name="index_pip_support">
    <inertial>
      <origin rpy="0 0 0" xyz="0 0 0"/>
      <mass value="0.0000000000001"/>
      <inertia ixx="0.00000000000001" ixy="0" ixz="0" iyy="0.00000000000001" iyz="0" izz="0.00000000000001"/>
    </inertial>
  </link>
  <joint name="index_pip_support" type="revolute">
    <parent link="index_mcp_2"/>
    <child link="index_pip_support"/>
    <origin rpy="0 0 0" xyz="-0.019513500000000003 0 0"/>
    <axis xyz="0 0 1"/>
    <limit effort="10" lower="-0.41538836197465046" upper="0.41538836197465046" velocity="1.0"/>
    <mimic joint="index_pip"/>
  </joint>
  <link name="index_pip">
    <visual>
      <origin rpy="0 0 0" xyz="0 0 0"/>
      <geometry>
        <mesh filename="package://hopejr_hand_description/meshes/visual/pip.dae" scale="0.1 0.1 0.1"/>
      </geometry>
    </visual>
    <collision>
      <origin rpy="0 0 0" xyz="0 0 0"/>
      <geometry>
        <mesh filename="package://hopejr_hand_description/meshes/collision/pip.stl" scale="0.1 0.1 0.1"/>
      </geometry>
    </collision>
    <inertial>
      <origin rpy="0 0 0" xyz="0 0 0"/>
      <mass value="0.005708"/>
      <inertia ixx="0.00000018835" ixy="0.00000001165" ixz="0.000000000165" iyy="0.000000372084" iyz="-0.000000000039" izz="0.00000039757"/>
    </inertial>
  </link>
  <joint name="index_pip" type="revolute">
    <parent link="index_pip_support"/>
    <child link="index_pip"/>
    <origin rpy="0 0 0" xyz="0.043500000000000004 0 0"/>
    <axis xyz="0 0 1"/>
    <limit effort="10" lower="-0.41538836197465046" upper="0.41538836197465046" velocity="1.0"/>
  </joint>
  <link name="index_dip_1_support">
    <inertial>
      <origin rpy="0 0 0" xyz="0 0 0"/>
      <mass value="0.0000000000001"/>
      <inertia ixx="0.00000000000001" ixy="0" ixz="0" iyy="0.00000000000001" iyz="0" izz="0.00000000000001"/>
    </inertial>
  </link>
  <joint name="index_dip_1_support" type="revolute">
    <parent link="index_pip"/>
    <child link="index_dip_1_support"/>
    <origin rpy="0 0 0" xyz="-0.0029132000000000003 0 0"/>
    <axis xyz="0 1 0"/>
    <limit effort="10" lower="0" upper="1.1780972450961724" velocity="1.0"/>
    <mimic joint="index_dip_1"/>
  </joint>
  <link name="index_dip_1">
    <visual>
      <origin rpy="0 0 0" xyz="0 0 0"/>
      <geometry>
        <mesh filename="package://hopejr_hand_description/meshes/visual/dip_1.dae" scale="0.1 0.1 0.1"/>
      </geometry>
    </visual>
    <collision>
      <origin rpy="0 0 0" xyz="0 0 0"/>
      <geometry>
        <mesh filename="package://hopejr_hand_description/meshes/collision/dip_1.stl" scale="0.1 0.1 0.1"/>
      </geometry>
    </collision>
    <inertial>
      <origin rpy="0 0 0" xyz="0 0 0"/>
      <mass value="0.005093"/>
      <inertia ixx="0.000000143621" ixy="-0.00000000003" ixz="0.000000000091" iyy="0.000000290288" iyz="-0.000000000079" izz="0.000000314107"/>
    </inertial>
  </link>
  <joint name="index_dip_1" type="revolute">
    <parent link="index_dip_1_support"/>
    <child link="index_dip_1"/>
    <origin rpy="0 0 0" xyz="0.0152 0 0"/>
    <axis xyz="0 1 0"/>
    <limit effort="10" lower="0" upper="1.1780972450961724" velocity="1.0"/>
  </joint>
  <link name="index_dip_2_support">
    <inertial>
      <origin rpy="0 0 0" xyz="0 0 0"/>
      <mass value="0.0000000000001"/>
      <inertia ixx="0.00000000000001" ixy="0" ixz="0" iyy="0.00000000000001" iyz="0" izz="0.00000000000001"/>
    </inertial>
  </link>
  <joint name="index_dip_2_support" type="revolute">
    <parent link="index_dip_1"/>
    <child link="index_dip_2_support"/>
    <origin rpy="0 0 0" xyz="0.0106 0 0"/>
    <axis xyz="0 1 0"/>
    <limit effort="10" lower="0" upper="1.1780972450961724" velocity="1.0"/>
    <mimic joint="index_dip_2"/>
  </joint>
  <link name="index_dip_2">
    <visual>
      <origin rpy="0 0 0" xyz="0 0 0"/>
      <geometry>
        <mesh filename="package://hopejr_hand_description/meshes/visual/dip_2.dae" scale="0.1 0.1 0.1"/>
      </geometry>
    </visual>
    <collision>
      <origin rpy="0 0 0" xyz="0 0 0"/>
      <geometry>
        <mesh filename="package://hopejr_hand_description/meshes/collision/dip_2.stl" scale="0.1 0.1 0.1"/>
      </geometry>
    </collision>
    <inertial>
      <origin rpy="0 0 0" xyz="0 0 0"/>
      <mass value="0.005429"/>
      <inertia ixx="0.000000155634" ixy="0.000000000003" ixz="-0.000000002159" iyy="0.000000339577" iyz="-0.000000000002" izz="0.000000357884"/>
    </inertial>
  </link>
  <joint name="index_dip_2" type="revolute">
    <parent link="index_dip_2_support"/>
    <child link="index_dip_2"/>
    <origin rpy="0 0 0" xyz="0.0152 0 0"/>
    <axis xyz="0 1 0"/>
    <limit effort="10" lower="0" upper="1.1780972450961724" velocity="1.0"/>
    <mimic joint="index_dip_1" multiplier="0.8" offset="0"/>
  </joint>
  <link name="middle_mcp_1">
    <visual>
      <origin rpy="0 0 0" xyz="0 0 0"/>
      <geometry>
        <mesh filename="package://hopejr_hand_description/meshes/visual/mcp_1.dae" scale="0.1 0.1 0.1"/>
      </geometry>
    </visual>
    <collision>
      <origin rpy="0 0 0" xyz="0 0 0"/>
      <geometry>
        <mesh filename="package://hopejr_hand_description/meshes/collision/mcp_1.stl" scale="0.1 0.1 0.1"/>
      </geometry>
    </collision>
    <inertial>
      <origin rpy="0 0 0" xyz="0 0 0"/>
      <mass value="0.004836"/>
      <inertia ixx="0.000000235908" ixy="-0.000000006556" ixz="0.000000001806" iyy="0.000000740439" iyz="0.000000000035" izz="0.000000830731"/>
    </inertial>
  </link>
  <joint name="middle_mcp_1" type="fixed">
    <parent link="hand"/>
    <child link="middle_mcp_1"/>
    <origin rpy="-1.3877985547232912 -1.5656650587940333 1.3991257415687344" xyz="0.0024581 0.007775400000000001 0.08732200000000001"/>
    <axis xyz="0 1 0"/>
  </joint>
  <link name="middle_mcp_2_support">
    <inertial>
      <origin rpy="0 0 0" xyz="0 0 0"/>
      <mass value="0.0000000000001"/>
      <inertia ixx="0.00000000000001" ixy="0" ixz="0" iyy="0.00000000000001" iyz="0" izz="0.00000000000001"/>
    </inertial>
  </link>
  <joint name="middle_mcp_2_support" type="revolute">
    <parent link="middle_mcp_1"/>
    <child link="middle_mcp_2_support"/>
    <origin rpy="0 0 0" xyz="0 0 0"/>
    <axis xyz="0 1 0"/>
    <limit effort="10" lower="0" upper="1.1780972450961724" velocity="1.0"/>
    <mimic joint="middle_mcp_2"/>
  </joint>
  <link name="middle_mcp_2">
    <visual>
      <origin rpy="0 0 0" xyz="0 0 0"/>
      <geometry>
        <mesh filename="package://hopejr_hand_description/meshes/visual/mcp_2.dae" scale="0.1 0.1 0.1"/>
      </geometry>
    </visual>
    <collision>
      <origin rpy="0 0 0" xyz="0 0 0"/>
      <geometry>
        <mesh filename="package://hopejr_hand_description/meshes/collision/mcp_2.stl" scale="0.1 0.1 0.1"/>
      </geometry>
    </collision>
    <inertial>
      <origin rpy="0 0 0" xyz="0 0 0"/>
      <mass value="0.001654"/>
      <inertia ixx="0.000000049479" ixy="0.000000000263" ixz="0.000000000299" iyy="0.000000032432" iyz="0.000000000057" izz="0.000000038462"/>
    </inertial>
  </link>
  <joint name="middle_mcp_2" type="revolute">
    <parent link="middle_mcp_2_support"/>
    <child link="middle_mcp_2"/>
    <origin rpy="0 0 0" xyz="0.0152 0 0"/>
    <axis xyz="0 1 0"/>
    <limit effort="10" lower="0" upper="1.1780972450961724" velocity="1.0"/>
  </joint>
  <link name="middle_pip_support">
    <inertial>
      <origin rpy="0 0 0" xyz="0 0 0"/>
      <mass value="0.0000000000001"/>
      <inertia ixx="0.00000000000001" ixy="0" ixz="0" iyy="0.00000000000001" iyz="0" izz="0.00000000000001"/>
    </inertial>
  </link>
  <joint name="middle_pip_support" type="revolute">
    <parent link="middle_mcp_2"/>
    <child link="middle_pip_support"/>
    <origin rpy="0 0 0" xyz="-0.019513500000000003 0 0"/>
    <axis xyz="0 0 1"/>
    <limit effort="10" lower="-0.41538836197465046" upper="0.41538836197465046" velocity="1.0"/>
    <mimic joint="middle_pip"/>
  </joint>
  <link name="middle_pip">
    <visual>
      <origin rpy="0 0 0" xyz="0 0 0"/>
      <geometry>
        <mesh filename="package://hopejr_hand_description/meshes/visual/pip.dae" scale="0.1 0.1 0.1"/>
      </geometry>
    </visual>
    <collision>
      <origin rpy="0 0 0" xyz="0 0 0"/>
      <geometry>
        <mesh filename="package://hopejr_hand_description/meshes/collision/pip.stl" scale="0.1 0.1 0.1"/>
      </geometry>
    </collision>
    <inertial>
      <origin rpy="0 0 0" xyz="0 0 0"/>
      <mass value="0.005708"/>
      <inertia ixx="0.00000018835" ixy="0.00000001165" ixz="0.000000000165" iyy="0.000000372084" iyz="-0.000000000039" izz="0.00000039757"/>
    </inertial>
  </link>
  <joint name="middle_pip" type="revolute">
    <parent link="middle_pip_support"/>
    <child link="middle_pip"/>
    <origin rpy="0 0 0" xyz="0.043500000000000004 0 0"/>
    <axis xyz="0 0 1"/>
    <limit effort="10" lower="-0.41538836197465046" upper="0.41538836197465046" velocity="1.0"/>
  </joint>
  <link name="middle_dip_1_support">
    <inertial>
      <origin rpy="0 0 0" xyz="0 0 0"/>
      <mass value="0.0000000000001"/>
      <inertia ixx="0.00000000000001" ixy="0" ixz="0" iyy="0.00000000000001" iyz="0" izz="0.00000000000001"/>
    </inertial>
  </link>
  <joint name="middle_dip_1_support" type="revolute">
    <parent link="middle_pip"/>
    <child link="middle_dip_1_support"/>
    <origin rpy="0 0 0" xyz="-0.0029132000000000003 0 0"/>
    <axis xyz="0 1 0"/>
    <limit effort="10" lower="0" upper="1.1780972450961724" velocity="1.0"/>
    <mimic joint="middle_dip_1"/>
  </joint>
  <link name="middle_dip_1">
    <visual>
      <origin rpy="0 0 0" xyz="0 0 0"/>
      <geometry>
        <mesh filename="package://hopejr_hand_description/meshes/visual/dip_1.dae" scale="0.1 0.1 0.1"/>
      </geometry>
    </visual>
    <collision>
      <origin rpy="0 0 0" xyz="0 0 0"/>
      <geometry>
        <mesh filename="package://hopejr_hand_description/meshes/collision/dip_1.stl" scale="0.1 0.1 0.1"/>
      </geometry>
    </collision>
    <inertial>
      <origin rpy="0 0 0" xyz="0 0 0"/>
      <mass value="0.005093"/>
      <inertia ixx="0.000000143621" ixy="-0.00000000003" ixz="0.000000000091" iyy="0.000000290288" iyz="-0.000000000079" izz="0.000000314107"/>
    </inertial>
  </link>
  <joint name="middle_dip_1" type="revolute">
    <parent link="middle_dip_1_support"/>
    <child link="middle_dip_1"/>
    <origin rpy="0 0 0" xyz="0.0152 0 0"/>
    <axis xyz="0 1 0"/>
    <limit effort="10" lower="0" upper="1.1780972450961724" velocity="1.0"/>
  </joint>
  <link name="middle_dip_2_support">
    <inertial>
      <origin rpy="0 0 0" xyz="0 0 0"/>
      <mass value="0.0000000000001"/>
      <inertia ixx="0.00000000000001" ixy="0" ixz="0" iyy="0.00000000000001" iyz="0" izz="0.00000000000001"/>
    </inertial>
  </link>
  <joint name="middle_dip_2_support" type="revolute">
    <parent link="middle_dip_1"/>
    <child link="middle_dip_2_support"/>
    <origin rpy="0 0 0" xyz="0.0106 0 0"/>
    <axis xyz="0 1 0"/>
    <limit effort="10" lower="0" upper="1.1780972450961724" velocity="1.0"/>
    <mimic joint="middle_dip_2"/>
  </joint>
  <link name="middle_dip_2">
    <visual>
      <origin rpy="0 0 0" xyz="0 0 0"/>
      <geometry>
        <mesh filename="package://hopejr_hand_description/meshes/visual/dip_2.dae" scale="0.1 0.1 0.1"/>
      </geometry>
    </visual>
    <collision>
      <origin rpy="0 0 0" xyz="0 0 0"/>
      <geometry>
        <mesh filename="package://hopejr_hand_description/meshes/collision/dip_2.stl" scale="0.1 0.1 0.1"/>
      </geometry>
    </collision>
    <inertial>
      <origin rpy="0 0 0" xyz="0 0 0"/>
      <mass value="0.005429"/>
      <inertia ixx="0.000000155634" ixy="0.000000000003" ixz="-0.000000002159" iyy="0.000000339577" iyz="-0.000000000002" izz="0.000000357884"/>
    </inertial>
  </link>
  <joint name="middle_dip_2" type="revolute">
    <parent link="middle_dip_2_support"/>
    <child link="middle_dip_2"/>
    <origin rpy="0 0 0" xyz="0.0152 0 0"/>
    <axis xyz="0 1 0"/>
    <limit effort="10" lower="0" upper="1.1780972450961724" velocity="1.0"/>
    <mimic joint="middle_dip_1" multiplier="0.8" offset="0"/>
  </joint>
  <link name="ring_mcp_1">
    <visual>
      <origin rpy="0 0 0" xyz="0 0 0"/>
      <geometry>
        <mesh filename="package://hopejr_hand_description/meshes/visual/mcp_1.dae" scale="0.1 0.1 0.1"/>
      </geometry>
    </visual>
    <collision>
      <origin rpy="0 0 0" xyz="0 0 0"/>
      <geometry>
        <mesh filename="package://hopejr_hand_description/meshes/collision/mcp_1.stl" scale="0.1 0.1 0.1"/>
      </geometry>
    </collision>
    <inertial>
      <origin rpy="0 0 0" xyz="0 0 0"/>
      <mass value="0.004836"/>
      <inertia ixx="0.000000235908" ixy="-0.000000006556" ixz="0.000000001806" iyy="0.000000740439" iyz="0.000000000035" izz="0.000000830731"/>
    </inertial>
  </link>
  <joint name="ring_mcp_1" type="fixed">
    <parent link="hand"/>
    <child link="ring_mcp_1"/>
    <origin rpy="-1.637136291663201 -1.7305812198149775 1.7657496042426633" xyz="0.0085778 -0.013244 0.08552"/>
    <axis xyz="0 1 0"/>
  </joint>
  <link name="ring_mcp_2_support">
    <inertial>
      <origin rpy="0 0 0" xyz="0 0 0"/>
      <mass value="0.0000000000001"/>
      <inertia ixx="0.00000000000001" ixy="0" ixz="0" iyy="0.00000000000001" iyz="0" izz="0.00000000000001"/>
    </inertial>
  </link>
  <joint name="ring_mcp_2_support" type="revolute">
    <parent link="ring_mcp_1"/>
    <child link="ring_mcp_2_support"/>
    <origin rpy="0 0 0" xyz="0 0 0"/>
    <axis xyz="0 1 0"/>
    <limit effort="10" lower="0" upper="1.1780972450961724" velocity="1.0"/>
    <mimic joint="ring_mcp_2"/>
  </joint>
  <link name="ring_mcp_2">
    <visual>
      <origin rpy="0 0 0" xyz="0 0 0"/>
      <geometry>
        <mesh filename="package://hopejr_hand_description/meshes/visual/mcp_2.dae" scale="0.1 0.1 0.1"/>
      </geometry>
    </visual>
    <collision>
      <origin rpy="0 0 0" xyz="0 0 0"/>
      <geometry>
        <mesh filename="package://hopejr_hand_description/meshes/collision/mcp_2.stl" scale="0.1 0.1 0.1"/>
      </geometry>
    </collision>
    <inertial>
      <origin rpy="0 0 0" xyz="0 0 0"/>
      <mass value="0.001654"/>
      <inertia ixx="0.000000049479" ixy="0.000000000263" ixz="0.000000000299" iyy="0.000000032432" iyz="0.000000000057" izz="0.000000038462"/>
    </inertial>
  </link>
  <joint name="ring_mcp_2" type="revolute">
    <parent link="ring_mcp_2_support"/>
    <child link="ring_mcp_2"/>
    <origin rpy="0 0 0" xyz="0.0152 0 0"/>
    <axis xyz="0 1 0"/>
    <limit effort="10" lower="0" upper="1.1780972450961724" velocity="1.0"/>
  </joint>
  <link name="ring_pip_support">
    <inertial>
      <origin rpy="0 0 0" xyz="0 0 0"/>
      <mass value="0.0000000000001"/>
      <inertia ixx="0.00000000000001" ixy="0" ixz="0" iyy="0.00000000000001" iyz="0" izz="0.00000000000001"/>
    </inertial>
  </link>
  <joint name="ring_pip_support" type="revolute">
    <parent link="ring_mcp_2"/>
    <child link="ring_pip_support"/>
    <origin rpy="0 0 0" xyz="-0.019513500000000003 0 0"/>
    <axis xyz="0 0 1"/>
    <limit effort="10" lower="-0.41538836197465046" upper="0.41538836197465046" velocity="1.0"/>
    <mimic joint="ring_pip"/>
  </joint>
  <link name="ring_pip">
    <visual>
      <origin rpy="0 0 0" xyz="0 0 0"/>
      <geometry>
        <mesh filename="package://hopejr_hand_description/meshes/visual/pip.dae" scale="0.1 0.1 0.1"/>
      </geometry>
    </visual>
    <collision>
      <origin rpy="0 0 0" xyz="0 0 0"/>
      <geometry>
        <mesh filename="package://hopejr_hand_description/meshes/collision/pip.stl" scale="0.1 0.1 0.1"/>
      </geometry>
    </collision>
    <inertial>
      <origin rpy="0 0 0" xyz="0 0 0"/>
      <mass value="0.005708"/>
      <inertia ixx="0.00000018835" ixy="0.00000001165" ixz="0.000000000165" iyy="0.000000372084" iyz="-0.000000000039" izz="0.00000039757"/>
    </inertial>
  </link>
  <joint name="ring_pip" type="revolute">
    <parent link="ring_pip_support"/>
    <child link="ring_pip"/>
    <origin rpy="0 0 0" xyz="0.043500000000000004 0 0"/>
    <axis xyz="0 0 1"/>
    <limit effort="10" lower="-0.41538836197465046" upper="0.41538836197465046" velocity="1.0"/>
  </joint>
  <link name="ring_dip_1_support">
    <inertial>
      <origin rpy="0 0 0" xyz="0 0 0"/>
      <mass value="0.0000000000001"/>
      <inertia ixx="0.00000000000001" ixy="0" ixz="0" iyy="0.00000000000001" iyz="0" izz="0.00000000000001"/>
    </inertial>
  </link>
  <joint name="ring_dip_1_support" type="revolute">
    <parent link="ring_pip"/>
    <child link="ring_dip_1_support"/>
    <origin rpy="0 0 0" xyz="-0.0029132000000000003 0 0"/>
    <axis xyz="0 1 0"/>
    <limit effort="10" lower="0" upper="1.1780972450961724" velocity="1.0"/>
    <mimic joint="ring_dip_1"/>
  </joint>
  <link name="ring_dip_1">
    <visual>
      <origin rpy="0 0 0" xyz="0 0 0"/>
      <geometry>
        <mesh filename="package://hopejr_hand_description/meshes/visual/dip_1.dae" scale="0.1 0.1 0.1"/>
      </geometry>
    </visual>
    <collision>
      <origin rpy="0 0 0" xyz="0 0 0"/>
      <geometry>
        <mesh filename="package://hopejr_hand_description/meshes/collision/dip_1.stl" scale="0.1 0.1 0.1"/>
      </geometry>
    </collision>
    <inertial>
      <origin rpy="0 0 0" xyz="0 0 0"/>
      <mass value="0.005093"/>
      <inertia ixx="0.000000143621" ixy="-0.00000000003" ixz="0.000000000091" iyy="0.000000290288" iyz="-0.000000000079" izz="0.000000314107"/>
    </inertial>
  </link>
  <joint name="ring_dip_1" type="revolute">
    <parent link="ring_dip_1_support"/>
    <child link="ring_dip_1"/>
    <origin rpy="0 0 0" xyz="0.0152 0 0"/>
    <axis xyz="0 1 0"/>
    <limit effort="10" lower="0" upper="1.1780972450961724" velocity="1.0"/>
  </joint>
  <link name="ring_dip_2_support">
    <inertial>
      <origin rpy="0 0 0" xyz="0 0 0"/>
      <mass value="0.0000000000001"/>
      <inertia ixx="0.00000000000001" ixy="0" ixz="0" iyy="0.00000000000001" iyz="0" izz="0.00000000000001"/>
    </inertial>
  </link>
  <joint name="ring_dip_2_support" type="revolute">
    <parent link="ring_dip_1"/>
    <child link="ring_dip_2_support"/>
    <origin rpy="0 0 0" xyz="0.0106 0 0"/>
    <axis xyz="0 1 0"/>
    <limit effort="10" lower="0" upper="1.1780972450961724" velocity="1.0"/>
    <mimic joint="ring_dip_2"/>
  </joint>
  <link name="ring_dip_2">
    <visual>
      <origin rpy="0 0 0" xyz="0 0 0"/>
      <geometry>
        <mesh filename="package://hopejr_hand_description/meshes/visual/dip_2.dae" scale="0.1 0.1 0.1"/>
      </geometry>
    </visual>
    <collision>
      <origin rpy="0 0 0" xyz="0 0 0"/>
      <geometry>
        <mesh filename="package://hopejr_hand_description/meshes/collision/dip_2.stl" scale="0.1 0.1 0.1"/>
      </geometry>
    </collision>
    <inertial>
      <origin rpy="0 0 0" xyz="0 0 0"/>
      <mass value="0.005429"/>
      <inertia ixx="0.000000155634" ixy="0.000000000003" ixz="-0.000000002159" iyy="0.000000339577" iyz="-0.000000000002" izz="0.000000357884"/>
    </inertial>
  </link>
  <joint name="ring_dip_2" type="revolute">
    <parent link="ring_dip_2_support"/>
    <child link="ring_dip_2"/>
    <origin rpy="0 0 0" xyz="0.0152 0 0"/>
    <axis xyz="0 1 0"/>
    <limit effort="10" lower="0" upper="1.1780972450961724" velocity="1.0"/>
    <mimic joint="ring_dip_1" multiplier="0.8" offset="0"/>
  </joint>
  <link name="pinky_mcp_1">
    <visual>
      <origin rpy="0 0 0" xyz="0 0 0"/>
      <geometry>
        <mesh filename="package://hopejr_hand_description/meshes/visual/mcp_1.dae" scale="0.1 0.1 0.1"/>
      </geometry>
    </visual>
    <collision>
      <origin rpy="0 0 0" xyz="0 0 0"/>
      <geometry>
        <mesh filename="package://hopejr_hand_description/meshes/collision/mcp_1.stl" scale="0.1 0.1 0.1"/>
      </geometry>
    </collision>
    <inertial>
      <origin rpy="0 0 0" xyz="0 0 0"/>
      <mass value="0.004836"/>
      <inertia ixx="0.000000235908" ixy="-0.000000006556" ixz="0.000000001806" iyy="0.000000740439" iyz="0.000000000035" izz="0.000000830731"/>
    </inertial>
  </link>
  <joint name="pinky_mcp_1" type="fixed">
    <parent link="hand"/>
    <child link="pinky_mcp_1"/>
    <origin rpy="-1.5403403313475954 -1.9259708295757425 1.7599900177110819" xyz="0.016965 -0.031494 0.077426"/>
    <axis xyz="0 1 0"/>
  </joint>
  <link name="pinky_mcp_2_support">
    <inertial>
      <origin rpy="0 0 0" xyz="0 0 0"/>
      <mass value="0.0000000000001"/>
      <inertia ixx="0.00000000000001" ixy="0" ixz="0" iyy="0.00000000000001" iyz="0" izz="0.00000000000001"/>
    </inertial>
  </link>
  <joint name="pinky_mcp_2_support" type="revolute">
    <parent link="pinky_mcp_1"/>
    <child link="pinky_mcp_2_support"/>
    <origin rpy="0 0 0" xyz="0 0 0"/>
    <axis xyz="0 1 0"/>
    <limit effort="10" lower="0" upper="1.1780972450961724" velocity="1.0"/>
    <mimic joint="pinky_mcp_2"/>
  </joint>
  <link name="pinky_mcp_2">
    <visual>
      <origin rpy="0 0 0" xyz="0 0 0"/>
      <geometry>
        <mesh filename="package://hopejr_hand_description/meshes/visual/mcp_2.dae" scale="0.1 0.1 0.1"/>
      </geometry>
    </visual>
    <collision>
      <origin rpy="0 0 0" xyz="0 0 0"/>
      <geometry>
        <mesh filename="package://hopejr_hand_description/meshes/collision/mcp_2.stl" scale="0.1 0.1 0.1"/>
      </geometry>
    </collision>
    <inertial>
      <origin rpy="0 0 0" xyz="0 0 0"/>
      <mass value="0.001654"/>
      <inertia ixx="0.000000049479" ixy="0.000000000263" ixz="0.000000000299" iyy="0.000000032432" iyz="0.000000000057" izz="0.000000038462"/>
    </inertial>
  </link>
  <joint name="pinky_mcp_2" type="revolute">
    <parent link="pinky_mcp_2_support"/>
    <child link="pinky_mcp_2"/>
    <origin rpy="0 0 0" xyz="0.0152 0 0"/>
    <axis xyz="0 1 0"/>
    <limit effort="10" lower="0" upper="1.1780972450961724" velocity="1.0"/>
  </joint>
  <link name="pinky_pip_support">
    <inertial>
      <origin rpy="0 0 0" xyz="0 0 0"/>
      <mass value="0.0000000000001"/>
      <inertia ixx="0.00000000000001" ixy="0" ixz="0" iyy="0.00000000000001" iyz="0" izz="0.00000000000001"/>
    </inertial>
  </link>
  <joint name="pinky_pip_support" type="revolute">
    <parent link="pinky_mcp_2"/>
    <child link="pinky_pip_support"/>
    <origin rpy="0 0 0" xyz="-0.019513500000000003 0 0"/>
    <axis xyz="0 0 1"/>
    <limit effort="10" lower="-0.41538836197465046" upper="0.41538836197465046" velocity="1.0"/>
    <mimic joint="pinky_pip"/>
  </joint>
  <link name="pinky_pip">
    <visual>
      <origin rpy="0 0 0" xyz="0 0 0"/>
      <geometry>
        <mesh filename="package://hopejr_hand_description/meshes/visual/pip.dae" scale="0.1 0.1 0.1"/>
      </geometry>
    </visual>
    <collision>
      <origin rpy="0 0 0" xyz="0 0 0"/>
      <geometry>
        <mesh filename="package://hopejr_hand_description/meshes/collision/pip.stl" scale="0.1 0.1 0.1"/>
      </geometry>
    </collision>
    <inertial>
      <origin rpy="0 0 0" xyz="0 0 0"/>
      <mass value="0.005708"/>
      <inertia ixx="0.00000018835" ixy="0.00000001165" ixz="0.000000000165" iyy="0.000000372084" iyz="-0.000000000039" izz="0.00000039757"/>
    </inertial>
  </link>
  <joint name="pinky_pip" type="revolute">
    <parent link="pinky_pip_support"/>
    <child link="pinky_pip"/>
    <origin rpy="0 0 0" xyz="0.043500000000000004 0 0"/>
    <axis xyz="0 0 1"/>
    <limit effort="10" lower="-0.41538836197465046" upper="0.41538836197465046" velocity="1.0"/>
  </joint>
  <link name="pinky_dip_1_support">
    <inertial>
      <origin rpy="0 0 0" xyz="0 0 0"/>
      <mass value="0.0000000000001"/>
      <inertia ixx="0.00000000000001" ixy="0" ixz="0" iyy="0.00000000000001" iyz="0" izz="0.00000000000001"/>
    </inertial>
  </link>
  <joint name="pinky_dip_1_support" type="revolute">
    <parent link="pinky_pip"/>
    <child link="pinky_dip_1_support"/>
    <origin rpy="0 0 0" xyz="-0.0029132000000000003 0 0"/>
    <axis xyz="0 1 0"/>
    <limit effort="10" lower="0" upper="1.1780972450961724" velocity="1.0"/>
    <mimic joint="pinky_dip_1"/>
  </joint>
  <link name="pinky_dip_1">
    <visual>
      <origin rpy="0 0 0" xyz="0 0 0"/>
      <geometry>
        <mesh filename="package://hopejr_hand_description/meshes/visual/dip_1.dae" scale="0.1 0.1 0.1"/>
      </geometry>
    </visual>
    <collision>
      <origin rpy="0 0 0" xyz="0 0 0"/>
      <geometry>
        <mesh filename="package://hopejr_hand_description/meshes/collision/dip_1.stl" scale="0.1 0.1 0.1"/>
      </geometry>
    </collision>
    <inertial>
      <origin rpy="0 0 0" xyz="0 0 0"/>
      <mass value="0.005093"/>
      <inertia ixx="0.000000143621" ixy="-0.00000000003" ixz="0.000000000091" iyy="0.000000290288" iyz="-0.000000000079" izz="0.000000314107"/>
    </inertial>
  </link>
  <joint name="pinky_dip_1" type="revolute">
    <parent link="pinky_dip_1_support"/>
    <child link="pinky_dip_1"/>
    <origin rpy="0 0 0" xyz="0.0152 0 0"/>
    <axis xyz="0 1 0"/>
    <limit effort="10" lower="0" upper="1.1780972450961724" velocity="1.0"/>
  </joint>
  <link name="pinky_dip_2_support">
    <inertial>
      <origin rpy="0 0 0" xyz="0 0 0"/>
      <mass value="0.0000000000001"/>
      <inertia ixx="0.00000000000001" ixy="0" ixz="0" iyy="0.00000000000001" iyz="0" izz="0.00000000000001"/>
    </inertial>
  </link>
  <joint name="pinky_dip_2_support" type="revolute">
    <parent link="pinky_dip_1"/>
    <child link="pinky_dip_2_support"/>
    <origin rpy="0 0 0" xyz="0.0106 0 0"/>
    <axis xyz="0 1 0"/>
    <limit effort="10" lower="0" upper="1.1780972450961724" velocity="1.0"/>
    <mimic joint="pinky_dip_2"/>
  </joint>
  <link name="pinky_dip_2">
    <visual>
      <origin rpy="0 0 0" xyz="0 0 0"/>
      <geometry>
        <mesh filename="package://hopejr_hand_description/meshes/visual/dip_2.dae" scale="0.1 0.1 0.1"/>
      </geometry>
    </visual>
    <collision>
      <origin rpy="0 0 0" xyz="0 0 0"/>
      <geometry>
        <mesh filename="package://hopejr_hand_description/meshes/collision/dip_2.stl" scale="0.1 0.1 0.1"/>
      </geometry>
    </collision>
    <inertial>
      <origin rpy="0 0 0" xyz="0 0 0"/>
      <mass value="0.005429"/>
      <inertia ixx="0.000000155634" ixy="0.000000000003" ixz="-0.000000002159" iyy="0.000000339577" iyz="-0.000000000002" izz="0.000000357884"/>
    </inertial>
  </link>
  <joint name="pinky_dip_2" type="revolute">
    <parent link="pinky_dip_2_support"/>
    <child link="pinky_dip_2"/>
    <origin rpy="0 0 0" xyz="0.0152 0 0"/>
    <axis xyz="0 1 0"/>
    <limit effort="10" lower="0" upper="1.1780972450961724" velocity="1.0"/>
    <mimic joint="pinky_dip_1" multiplier="0.8" offset="0"/>
  </joint>
  <joint name="base_link_fixed" type="fixed">
    <parent link="base_footprint"/>
    <child link="base_link"/>
    <origin rpy="0 0 0" xyz="0 0 0"/>
  </joint>
</robot>
